#VRML_SIM R2023a utf8

EXTERNPROTO "https://raw.githubusercontent.com/cyberbotics/webots/R2023a/projects/objects/floors/protos/RectangleArena.proto"
EXTERNPROTO "https://raw.githubusercontent.com/cyberbotics/webots/R2023a/projects/objects/backgrounds/protos/TexturedBackground.proto"
EXTERNPROTO "https://raw.githubusercontent.com/cyberbotics/webots/R2023a/projects/objects/backgrounds/protos/TexturedBackgroundLight.proto"

WorldInfo {
}
Viewpoint {
  orientation -0.5773502691896258 0.5773502691896258 0.5773502691896258 2.0944
  position 1.5002128551658955 1.5000099218289764 5.656092365411376
}
TexturedBackground {
}
TexturedBackgroundLight {
}
RectangleArena {
  translation 1.5 1.5 0
  floorSize 3 3
}
Robot {
  translation 0.125 0.124908 0.0676659
  rotation 1 0 0 1.58
  children [
    Compass {
      boundingObject Box {
        size 0.05 0.05 0.05
      }
      physics Physics {
      }
    }
    GPS {
    }
    DistanceSensor {
      translation -0.025 0.03 0
      rotation 0 1 0 -3.123185307179586
      children [
        Shape {
          appearance PBRAppearance {
            baseColor 1 0 0
            metalness 0.5
          }
          geometry Box {
            size 0.01 0.01 0.01
          }
        }
      ]
      name "Right_distance"
    }
    DistanceSensor {
      translation 0.025 0.03 0
      rotation 0 1 0 0
      children [
        Shape {
          appearance PBRAppearance {
            baseColor 1 0 0
            metalness 0.5
          }
          geometry Box {
            size 0.01 0.01 0.01
          }
        }
      ]
      name "Left_distance"
    }
    DistanceSensor {
      translation 0 0.03 0.08
      rotation 0 1 0 -1.58
      children [
        Shape {
          appearance PBRAppearance {
            baseColor 1 0 0
            metalness 0.5
          }
          geometry Box {
            size 0.01 0.01 0.01
          }
        }
      ]
      name "Front_distance"
    }
    DEF Joint4 HingeJoint {
      jointParameters HingeJointParameters {
        position 7.937916130258282
        anchor -0.05500000000000001 -0.014999999999999984 -0.050000000000000024
      }
      device [
        PositionSensor {
          name "position4"
        }
        RotationalMotor {
          name "Motor4"
        }
      ]
      endPoint Solid {
        translation -0.05499868021808561 -0.014995040585743193 -0.050004384402199
        rotation 0.2520134987852769 0.9337013392006976 0.25434426591693954 1.648521818798379
        children [
          DEF Wheel4 Shape {
            appearance PBRAppearance {
              baseColor 0 0 0
              metalness 0
            }
            geometry Cylinder {
              height 0.02
              radius 0.043
            }
          }
        ]
        name "solid(3)"
        boundingObject USE Wheel4
        physics Physics {
        }
      }
    }
    DEF Joint3 HingeJoint {
      jointParameters HingeJointParameters {
        position 7.937911565181848
        anchor 0.05500000000000014 -0.015000000000000015 -0.05000000000000005
      }
      device [
        PositionSensor {
          name "position3"
        }
        RotationalMotor {
          name "Motor3"
        }
      ]
      endPoint Solid {
        translation 0.055001296361069124 -0.014994540030148006 -0.05000490454921915
        rotation 0.2523006566419382 0.9335447243833667 0.2546342990133709 1.6486889259495898
        children [
          DEF Wheel3 Shape {
            appearance PBRAppearance {
              baseColor 0 0 0
              metalness 0
            }
            geometry Cylinder {
              height 0.02
              radius 0.043
            }
          }
        ]
        name "solid(2)"
        boundingObject USE Wheel3
        physics Physics {
        }
      }
    }
    DEF Joint2 HingeJoint {
      jointParameters HingeJointParameters {
        position 7.9379178310010845
        anchor -0.055 -0.015000000000000024 0.050000000000000044
      }
      device [
        PositionSensor {
          name "position2"
        }
        RotationalMotor {
          name "Motor2"
        }
      ]
      endPoint Solid {
        translation -0.05500130005965888 -0.014995064833256293 0.04999551226446072
        rotation 0.2520142611086078 0.9337009340220116 0.2543449979934843 1.6485221515376045
        children [
          DEF Wheel2 Shape {
            appearance PBRAppearance {
              baseColor 0 0 0
              metalness 0
            }
            geometry Cylinder {
              height 0.02
              radius 0.043
            }
          }
        ]
        name "solid(1)"
        boundingObject USE Wheel2
        physics Physics {
        }
      }
    }
    DEF Joint1 HingeJoint {
      jointParameters HingeJointParameters {
        position 7.937913073830743
        anchor 0.05499999999999986 -0.014999999999999989 0.04999999999999995
      }
      device [
        PositionSensor {
          name "position1"
        }
        RotationalMotor {
          name "Motor1"
        }
      ]
      endPoint Solid {
        translation 0.05499867644280039 -0.014994566117810781 0.04999498793524181
        rotation 0.25230136203977854 0.9335443540062862 0.25463495796111363 1.6486892299997664
        children [
          DEF Wheel1 Shape {
            appearance PBRAppearance {
              baseColor 0 0 0
              metalness 0
            }
            geometry Cylinder {
              height 0.02
              radius 0.043
            }
          }
        ]
        boundingObject USE Wheel1
        physics Physics {
        }
      }
    }
    DEF Body Group {
      children [
        DEF Leg4 Transform {
          translation -0.041 -0.015 -0.05
          rotation 0 1 0 1.58
          children [
            Shape {
              appearance PBRAppearance {
                baseColor 0 0 1
                metalness 0.5
              }
              geometry Cylinder {
                height 0.05
                radius 0.0175
              }
            }
          ]
        }
        DEF Leg3 Transform {
          translation 0.041 -0.015 -0.05
          rotation 0 1 0 1.58
          children [
            Shape {
              appearance PBRAppearance {
                baseColor 0 0 1
                metalness 0.5
              }
              geometry Cylinder {
                height 0.05
                radius 0.0175
              }
            }
          ]
        }
        DEF Leg2 Transform {
          translation -0.041 -0.015 0.05
          rotation 0 1 0 1.58
          children [
            Shape {
              appearance PBRAppearance {
                baseColor 0 0 1
                metalness 0.5
              }
              geometry Cylinder {
                height 0.05
                radius 0.0175
              }
            }
          ]
        }
        DEF Leg1 Transform {
          translation 0.041 -0.015 0.05
          rotation 0 1 0 1.58
          children [
            Shape {
              appearance PBRAppearance {
                baseColor 0 0 1
                metalness 0.5
              }
              geometry Cylinder {
                height 0.05
                radius 0.0175
              }
            }
          ]
        }
        DEF Capsule Shape {
          appearance PBRAppearance {
            baseColor 0 0 1
            metalness 0.5
          }
          geometry Capsule {
            height 0.12
            radius 0.04
          }
        }
      ]
    }
  ]
  boundingObject USE Body
  physics Physics {
  }
  controller "BD_test_wavefront_1"
}
DEF wall_x Solid {
  translation 0.375 0.175 0
  children [
    Shape {
      appearance PBRAppearance {
        baseColor 0 0 0
        roughness 1
        metalness 0
      }
      geometry Box {
        size 0.125 0.375 0.25
      }
    }
  ]
  name "wall"
}
DEF wall_x Solid {
  translation 0.875 2.5 0
  children [
    Shape {
      appearance PBRAppearance {
        baseColor 0 0 0
        roughness 1
        metalness 0
      }
      geometry Box {
        size 0.125 0.375 0.25
      }
    }
  ]
  name "wall(17)"
}
DEF wall_x Solid {
  translation 0.375 2.5 0
  children [
    Shape {
      appearance PBRAppearance {
        baseColor 0 0 0
        roughness 1
        metalness 0
      }
      geometry Box {
        size 0.125 0.375 0.25
      }
    }
  ]
  name "wall(20)"
}
DEF wall_x Solid {
  translation 0.225 2.625 0
  rotation 0 0 1 1.5708
  children [
    Shape {
      appearance PBRAppearance {
        baseColor 0 0 0
        roughness 1
        metalness 0
      }
      geometry Box {
        size 0.125 0.4125 0.25
      }
    }
  ]
  name "wall(21)"
}
DEF wall_x Solid {
  translation 2.675 2.375 0
  rotation 0 0 1 1.5708
  children [
    Shape {
      appearance PBRAppearance {
        baseColor 0 0 0
        roughness 1
        metalness 0
      }
      geometry Box {
        size 0.125 0.625 0.25
      }
    }
  ]
  name "wall(25)"
}
DEF wall_x Solid {
  translation 1.375 2.87 0
  children [
    Shape {
      appearance PBRAppearance {
        baseColor 0 0 0
        roughness 1
        metalness 0
      }
      geometry Box {
        size 0.125 0.25 0.25
      }
    }
  ]
  name "wall(19)"
}
DEF wall_x Solid {
  translation 1.875 1.875 0
  children [
    Shape {
      appearance PBRAppearance {
        baseColor 0 0 0
        roughness 1
        metalness 0
      }
      geometry Box {
        size 0.125 0.125 0.25
      }
    }
  ]
  name "wall(24)"
}
DEF wall_x Solid {
  translation 2.375 2.87 0
  children [
    Shape {
      appearance PBRAppearance {
        baseColor 0 0 0
        roughness 1
        metalness 0
      }
      geometry Box {
        size 0.125 0.25 0.25
      }
    }
  ]
  name "wall(22)"
}
DEF wall_x Solid {
  translation 1.875 2.5 0
  children [
    Shape {
      appearance PBRAppearance {
        baseColor 0 0 0
        roughness 1
        metalness 0
      }
      geometry Box {
        size 0.125 0.375 0.25
      }
    }
  ]
  name "wall(18)"
}
DEF wall_x Solid {
  translation 0.375 1.575 0
  children [
    Shape {
      appearance PBRAppearance {
        baseColor 0 0 0
        roughness 1
        metalness 0
      }
      geometry Box {
        size 0.125 0.525 0.25
      }
    }
  ]
  name "wall(8)"
}
DEF wall_x Solid {
  translation 0.8625 1.125 0
  rotation 0 1 0 0
  children [
    Shape {
      appearance PBRAppearance {
        baseColor 0 0 0
        roughness 1
        metalness 0
      }
      geometry Box {
        size 0.125 0.525 0.25
      }
    }
  ]
  name "wall(9)"
}
DEF wall_x Solid {
  translation 1.3725 1.735 0
  rotation 0 1 0 0
  children [
    Shape {
      appearance PBRAppearance {
        baseColor 0 0 0
        roughness 1
        metalness 0
      }
      geometry Box {
        size 0.125 1.35 0.25
      }
    }
  ]
  name "wall(12)"
}
DEF wall_x Solid {
  translation 1.375 0.5 0
  children [
    Shape {
      appearance PBRAppearance {
        baseColor 0 0 0
        roughness 1
        metalness 0
      }
      geometry Box {
        size 0.125 0.375 0.25
      }
    }
  ]
  name "wall(2)"
}
DEF wall_x Solid {
  translation 1.875 0.625 0
  children [
    Shape {
      appearance PBRAppearance {
        baseColor 0 0 0
        roughness 1
        metalness 0
      }
      geometry Box {
        size 0.125 0.625 0.25
      }
    }
  ]
  name "wall(4)"
}
DEF wall_x Solid {
  translation 2.375 1.375 0
  children [
    Shape {
      appearance PBRAppearance {
        baseColor 0 0 0
        roughness 1
        metalness 0
      }
      geometry Box {
        size 0.125 0.625 0.25
      }
    }
  ]
  name "wall(14)"
}
DEF wall_x Solid {
  translation 2.375 2.25 0
  children [
    Shape {
      appearance PBRAppearance {
        baseColor 0 0 0
        roughness 1
        metalness 0
      }
      geometry Box {
        size 0.125 0.376 0.25
      }
    }
  ]
  name "wall(23)"
}
DEF wall_y Solid {
  translation 0.875 0.375 -2.33179e-06
  rotation -2.327229999987396e-06 -2.327229999987396e-06 -0.9999999999945841 -1.5707953071795862
  children [
    Shape {
      appearance PBRAppearance {
        baseColor 0 0 0
        roughness 1
        metalness 0
      }
      geometry Box {
        size 0.125 1.125 0.25
      }
    }
  ]
  name "wall(1)"
}
DEF wall_y Solid {
  translation 0.6375 0.875 -1.26131e-06
  rotation -2.327229999987396e-06 -2.327229999987396e-06 -0.9999999999945841 -1.5707953071795862
  children [
    Shape {
      appearance PBRAppearance {
        baseColor 0 0 0
        roughness 1
        metalness 0
      }
      geometry Box {
        size 0.125 0.575 0.25
      }
    }
  ]
  name "wall(6)"
}
DEF wall_y Solid {
  translation 1.0875 1.125 -3.35578e-06
  rotation -2.327229999987396e-06 -2.327229999987396e-06 -0.9999999999945841 -1.5707953071795862
  children [
    Shape {
      appearance PBRAppearance {
        baseColor 0 0 0
        roughness 1
        metalness 0
      }
      geometry Box {
        size 0.125 0.575 0.25
      }
    }
  ]
  name "wall(10)"
}
DEF wall_y Solid {
  translation 0.6 1.875 -1.12174e-06
  rotation -2.327229999987396e-06 -2.327229999987396e-06 -0.9999999999945841 -1.5707953071795862
  children [
    Shape {
      appearance PBRAppearance {
        baseColor 0 0 0
        roughness 1
        metalness 0
      }
      geometry Box {
        size 0.125 0.575 0.25
      }
    }
  ]
  name "wall(11)"
}
DEF wall_y Solid {
  translation 1.36 2.375 -4.65918e-06
  rotation -2.327229999987396e-06 -2.327229999987396e-06 -0.9999999999945841 -1.5707953071795862
  children [
    Shape {
      appearance PBRAppearance {
        baseColor 0 0 0
        roughness 1
        metalness 0
      }
      geometry Box {
        size 0.125 1 0.25
      }
    }
  ]
  name "wall(13)"
}
DEF wall_y Solid {
  translation 0.175 1.375 7.40095e-07
  rotation -2.327229999987396e-06 -2.327229999987396e-06 -0.9999999999945841 -1.5707953071795862
  children [
    Shape {
      appearance PBRAppearance {
        baseColor 0 0 0
        roughness 1
        metalness 0
      }
      geometry Box {
        size 0.125 0.35 0.25
      }
    }
  ]
  name "wall(7)"
}
DEF wall_y Solid {
  translation 2.25 0.375 -8.8014e-06
  rotation -2.327229999987396e-06 -2.327229999987396e-06 -0.9999999999945841 -1.5707953071795862
  children [
    Shape {
      appearance PBRAppearance {
        baseColor 0 0 0
        roughness 1
        metalness 0
      }
      geometry Box {
        size 0.125 0.825 0.25
      }
    }
  ]
  name "wall(5)"
}
DEF wall_y Solid {
  translation 1.6 0.625 -5.68287e-06
  rotation -2.327229999987396e-06 -2.327229999987396e-06 -0.9999999999945841 -1.5707953071795862
  children [
    Shape {
      appearance PBRAppearance {
        baseColor 0 0 0
        roughness 1
        metalness 0
      }
      geometry Box {
        size 0.125 0.575 0.25
      }
    }
  ]
  name "wall(3)"
}
DEF wall_y Solid {
  translation 1.85 1.375 -6.84642e-06
  rotation -2.327229999987396e-06 -2.327229999987396e-06 -0.9999999999945841 -1.5707953071795862
  children [
    Shape {
      appearance PBRAppearance {
        baseColor 0 0 0
        roughness 1
        metalness 0
      }
      geometry Box {
        size 0.125 0.95 0.25
      }
    }
  ]
  name "wall(16)"
}
DEF wall_x Solid {
  translation 1.875 0.625 0
  children [
    Shape {
      appearance PBRAppearance {
        baseColor 0 0 0
        roughness 1
        metalness 0
      }
      geometry Box {
        size 0.125 0.625 0.25
      }
    }
  ]
  name "wall(15)"
}
